urllib3.exceptions.SSLError: EOF occurred in violation of protocol (_ssl.c:997)

The above exception was the direct cause of the following exception:

urllib3.exceptions.ProxyError: ('Unable to connect to proxy', SSLError(SSLEOFError(8, 'EOF occurred in violation of protocol (_ssl.c:997)')))

The above exception was the direct cause of the following exception:

Traceback (most recent call last):
  File "D:\developing\Python310\lib\site-packages\requests\adapters.py", line 486, in send
    resp = conn.urlopen(
  File "D:\developing\Python310\lib\site-packages\urllib3\connectionpool.py", line 844, in urlopen
    retries = retries.increment(
  File "D:\developing\Python310\lib\site-packages\urllib3\util\retry.py", line 515, in increment
    raise MaxRetryError(_pool, url, reason) from reason  # type: ignore[arg-type]
urllib3.exceptions.MaxRetryError: HTTPSConnectionPool(host='ghxcx.lovestu.com', port=443): Max retries exceeded with url: /api/index/today_secret (Caused by ProxyError('Unable to connect to proxy', SSLError(SSLEOFError(8, 'EOF occurred in violation of protocol (_ssl.c:997)'))))

During handling of the above exception, another exception occurred:

Traceback (most recent call last):
  File "D:\git_repo\MusicHelper\main.py", line 1026, in <module>
    code = music.get_code()
  File "D:\git_repo\MusicHelper\main.py", line 361, in get_code
    req = requests.get("https://ghxcx.lovestu.com/api/index/today_secret")
  File "D:\developing\Python310\lib\site-packages\requests\api.py", line 73, in get
    return request("get", url, params=params, **kwargs)
  File "D:\developing\Python310\lib\site-packages\requests\api.py", line 59, in request
    return session.request(method=method, url=url, **kwargs)
  File "D:\developing\Python310\lib\site-packages\requests\sessions.py", line 589, in request
    resp = self.send(prep, **send_kwargs)
  File "D:\developing\Python310\lib\site-packages\requests\sessions.py", line 703, in send
    r = adapter.send(request, **kwargs)
  File "D:\developing\Python310\lib\site-packages\requests\adapters.py", line 513, in send
    raise ProxyError(e, request=request)
requests.exceptions.ProxyError: HTTPSConnectionPool(host='ghxcx.lovestu.com', port=443): Max retries exceeded with url: /api/index/today_secret (Caused by ProxyError('Unable to connect to proxy', SSLError(SSLEOFError(8, 'EOF occurred in violation of protocol (_ssl.c:997)'))))
urllib3.exceptions.SSLError: EOF occurred in violation of protocol (_ssl.c:997)

The above exception was the direct cause of the following exception:

urllib3.exceptions.ProxyError: ('Unable to connect to proxy', SSLError(SSLEOFError(8, 'EOF occurred in violation of protocol (_ssl.c:997)')))

The above exception was the direct cause of the following exception:

Traceback (most recent call last):
  File "D:\developing\Python310\lib\site-packages\requests\adapters.py", line 486, in send
    resp = conn.urlopen(
  File "D:\developing\Python310\lib\site-packages\urllib3\connectionpool.py", line 844, in urlopen
    retries = retries.increment(
  File "D:\developing\Python310\lib\site-packages\urllib3\util\retry.py", line 515, in increment
    raise MaxRetryError(_pool, url, reason) from reason  # type: ignore[arg-type]
urllib3.exceptions.MaxRetryError: HTTPSConnectionPool(host='ghxcx.lovestu.com', port=443): Max retries exceeded with url: /api/index/today_secret (Caused by ProxyError('Unable to connect to proxy', SSLError(SSLEOFError(8, 'EOF occurred in violation of protocol (_ssl.c:997)'))))

During handling of the above exception, another exception occurred:

Traceback (most recent call last):
  File "D:\git_repo\MusicHelper\main.py", line 1026, in <module>
    code = music.get_code()
  File "D:\git_repo\MusicHelper\main.py", line 361, in get_code
    req = requests.get("https://ghxcx.lovestu.com/api/index/today_secret")
  File "D:\developing\Python310\lib\site-packages\requests\api.py", line 73, in get
    return request("get", url, params=params, **kwargs)
  File "D:\developing\Python310\lib\site-packages\requests\api.py", line 59, in request
    return session.request(method=method, url=url, **kwargs)
  File "D:\developing\Python310\lib\site-packages\requests\sessions.py", line 589, in request
    resp = self.send(prep, **send_kwargs)
  File "D:\developing\Python310\lib\site-packages\requests\sessions.py", line 703, in send
    r = adapter.send(request, **kwargs)
  File "D:\developing\Python310\lib\site-packages\requests\adapters.py", line 513, in send
    raise ProxyError(e, request=request)
requests.exceptions.ProxyError: HTTPSConnectionPool(host='ghxcx.lovestu.com', port=443): Max retries exceeded with url: /api/index/today_secret (Caused by ProxyError('Unable to connect to proxy', SSLError(SSLEOFError(8, 'EOF occurred in violation of protocol (_ssl.c:997)'))))
